{
 "cells": [
  {
   "cell_type": "code",
   "execution_count": 1,
   "metadata": {},
   "outputs": [
    {
     "name": "stderr",
     "output_type": "stream",
     "text": [
      "ERROR:root:Internal Python error in the inspect module.\n",
      "Below is the traceback from this internal error.\n",
      "\n",
      "ERROR:root:Internal Python error in the inspect module.\n",
      "Below is the traceback from this internal error.\n",
      "\n"
     ]
    },
    {
     "name": "stdout",
     "output_type": "stream",
     "text": [
      "Traceback (most recent call last):\n",
      "  File \"/usr/lib/python3.6/pkgutil.py\", line 412, in get_importer\n",
      "    importer = sys.path_importer_cache[path_item]\n",
      "KeyError: ''\n",
      "\n",
      "During handling of the above exception, another exception occurred:\n",
      "\n",
      "Traceback (most recent call last):\n",
      "  File \"/usr/local/lib/python3.6/dist-packages/IPython/core/interactiveshell.py\", line 3331, in run_code\n",
      "    exec(code_obj, self.user_global_ns, self.user_ns)\n",
      "  File \"<ipython-input-1-4fd4413739ff>\", line 1, in <module>\n",
      "    import autokeras as ak\n",
      "  File \"/usr/local/lib/python3.6/dist-packages/autokeras/__init__.py\", line 15, in <module>\n",
      "    from autokeras.auto_model import AutoModel\n",
      "  File \"/usr/local/lib/python3.6/dist-packages/autokeras/auto_model.py\", line 22, in <module>\n",
      "    import tensorflow as tf\n",
      "  File \"/usr/local/lib/python3.6/dist-packages/tensorflow/__init__.py\", line 41, in <module>\n",
      "    from tensorflow.python.tools import module_util as _module_util\n",
      "  File \"/usr/local/lib/python3.6/dist-packages/tensorflow/python/__init__.py\", line 40, in <module>\n",
      "    from tensorflow.python.eager import context\n",
      "  File \"/usr/local/lib/python3.6/dist-packages/tensorflow/python/eager/context.py\", line 32, in <module>\n",
      "    from tensorflow.core.framework import function_pb2\n",
      "  File \"/usr/local/lib/python3.6/dist-packages/tensorflow/core/framework/function_pb2.py\", line 7, in <module>\n",
      "    from google.protobuf import descriptor as _descriptor\n",
      "  File \"/usr/local/lib/python3.6/dist-packages/google/protobuf/__init__.py\", line 37, in <module>\n",
      "    __import__('pkg_resources').declare_namespace(__name__)\n",
      "  File \"/usr/local/lib/python3.6/dist-packages/pkg_resources/__init__.py\", line 3258, in <module>\n",
      "    @_call_aside\n",
      "  File \"/usr/local/lib/python3.6/dist-packages/pkg_resources/__init__.py\", line 3242, in _call_aside\n",
      "    f(*args, **kwargs)\n",
      "  File \"/usr/local/lib/python3.6/dist-packages/pkg_resources/__init__.py\", line 3271, in _initialize_master_working_set\n",
      "    working_set = WorkingSet._build_master()\n",
      "  File \"/usr/local/lib/python3.6/dist-packages/pkg_resources/__init__.py\", line 575, in _build_master\n",
      "    ws = cls()\n",
      "  File \"/usr/local/lib/python3.6/dist-packages/pkg_resources/__init__.py\", line 568, in __init__\n",
      "    self.add_entry(entry)\n",
      "  File \"/usr/local/lib/python3.6/dist-packages/pkg_resources/__init__.py\", line 624, in add_entry\n",
      "    for dist in find_distributions(entry, True):\n",
      "  File \"/usr/local/lib/python3.6/dist-packages/pkg_resources/__init__.py\", line 1971, in find_distributions\n",
      "    importer = get_importer(path_item)\n",
      "  File \"/usr/lib/python3.6/pkgutil.py\", line 416, in get_importer\n",
      "    importer = path_hook(path_item)\n",
      "  File \"<frozen importlib._bootstrap_external>\", line 1324, in path_hook_for_FileFinder\n",
      "  File \"<frozen importlib._bootstrap_external>\", line 102, in _path_isdir\n",
      "FileNotFoundError: [Errno 2] No such file or directory\n",
      "\n",
      "During handling of the above exception, another exception occurred:\n",
      "\n",
      "Traceback (most recent call last):\n",
      "  File \"/usr/local/lib/python3.6/dist-packages/IPython/core/interactiveshell.py\", line 2044, in showtraceback\n",
      "    stb = value._render_traceback_()\n",
      "AttributeError: 'FileNotFoundError' object has no attribute '_render_traceback_'\n",
      "\n",
      "During handling of the above exception, another exception occurred:\n",
      "\n",
      "Traceback (most recent call last):\n",
      "  File \"/usr/local/lib/python3.6/dist-packages/IPython/core/ultratb.py\", line 1148, in get_records\n",
      "    return _fixed_getinnerframes(etb, number_of_lines_of_context, tb_offset)\n",
      "  File \"/usr/local/lib/python3.6/dist-packages/IPython/core/ultratb.py\", line 316, in wrapped\n",
      "    return f(*args, **kwargs)\n",
      "  File \"/usr/local/lib/python3.6/dist-packages/IPython/core/ultratb.py\", line 350, in _fixed_getinnerframes\n",
      "    records = fix_frame_records_filenames(inspect.getinnerframes(etb, context))\n",
      "  File \"/usr/lib/python3.6/inspect.py\", line 1490, in getinnerframes\n",
      "    frameinfo = (tb.tb_frame,) + getframeinfo(tb, context)\n",
      "  File \"/usr/lib/python3.6/inspect.py\", line 1448, in getframeinfo\n",
      "    filename = getsourcefile(frame) or getfile(frame)\n",
      "  File \"/usr/lib/python3.6/inspect.py\", line 696, in getsourcefile\n",
      "    if getattr(getmodule(object, filename), '__loader__', None) is not None:\n",
      "  File \"/usr/lib/python3.6/inspect.py\", line 725, in getmodule\n",
      "    file = getabsfile(object, _filename)\n",
      "  File \"/usr/lib/python3.6/inspect.py\", line 709, in getabsfile\n",
      "    return os.path.normcase(os.path.abspath(_filename))\n",
      "  File \"/usr/lib/python3.6/posixpath.py\", line 383, in abspath\n",
      "    cwd = os.getcwd()\n",
      "FileNotFoundError: [Errno 2] No such file or directory\n",
      "Traceback (most recent call last):\n",
      "  File \"/usr/lib/python3.6/pkgutil.py\", line 412, in get_importer\n",
      "    importer = sys.path_importer_cache[path_item]\n",
      "KeyError: ''\n",
      "\n",
      "During handling of the above exception, another exception occurred:\n",
      "\n",
      "Traceback (most recent call last):\n",
      "  File \"/usr/local/lib/python3.6/dist-packages/IPython/core/interactiveshell.py\", line 3331, in run_code\n",
      "    exec(code_obj, self.user_global_ns, self.user_ns)\n",
      "  File \"<ipython-input-1-4fd4413739ff>\", line 1, in <module>\n",
      "    import autokeras as ak\n",
      "  File \"/usr/local/lib/python3.6/dist-packages/autokeras/__init__.py\", line 15, in <module>\n",
      "    from autokeras.auto_model import AutoModel\n",
      "  File \"/usr/local/lib/python3.6/dist-packages/autokeras/auto_model.py\", line 22, in <module>\n",
      "    import tensorflow as tf\n",
      "  File \"/usr/local/lib/python3.6/dist-packages/tensorflow/__init__.py\", line 41, in <module>\n",
      "    from tensorflow.python.tools import module_util as _module_util\n",
      "  File \"/usr/local/lib/python3.6/dist-packages/tensorflow/python/__init__.py\", line 40, in <module>\n",
      "    from tensorflow.python.eager import context\n",
      "  File \"/usr/local/lib/python3.6/dist-packages/tensorflow/python/eager/context.py\", line 32, in <module>\n",
      "    from tensorflow.core.framework import function_pb2\n",
      "  File \"/usr/local/lib/python3.6/dist-packages/tensorflow/core/framework/function_pb2.py\", line 7, in <module>\n",
      "    from google.protobuf import descriptor as _descriptor\n",
      "  File \"/usr/local/lib/python3.6/dist-packages/google/protobuf/__init__.py\", line 37, in <module>\n",
      "    __import__('pkg_resources').declare_namespace(__name__)\n",
      "  File \"/usr/local/lib/python3.6/dist-packages/pkg_resources/__init__.py\", line 3258, in <module>\n",
      "    @_call_aside\n",
      "  File \"/usr/local/lib/python3.6/dist-packages/pkg_resources/__init__.py\", line 3242, in _call_aside\n",
      "    f(*args, **kwargs)\n",
      "  File \"/usr/local/lib/python3.6/dist-packages/pkg_resources/__init__.py\", line 3271, in _initialize_master_working_set\n",
      "    working_set = WorkingSet._build_master()\n",
      "  File \"/usr/local/lib/python3.6/dist-packages/pkg_resources/__init__.py\", line 575, in _build_master\n",
      "    ws = cls()\n",
      "  File \"/usr/local/lib/python3.6/dist-packages/pkg_resources/__init__.py\", line 568, in __init__\n",
      "    self.add_entry(entry)\n",
      "  File \"/usr/local/lib/python3.6/dist-packages/pkg_resources/__init__.py\", line 624, in add_entry\n",
      "    for dist in find_distributions(entry, True):\n",
      "  File \"/usr/local/lib/python3.6/dist-packages/pkg_resources/__init__.py\", line 1971, in find_distributions\n",
      "    importer = get_importer(path_item)\n",
      "  File \"/usr/lib/python3.6/pkgutil.py\", line 416, in get_importer\n",
      "    importer = path_hook(path_item)\n",
      "  File \"<frozen importlib._bootstrap_external>\", line 1324, in path_hook_for_FileFinder\n",
      "  File \"<frozen importlib._bootstrap_external>\", line 102, in _path_isdir\n",
      "FileNotFoundError: [Errno 2] No such file or directory\n",
      "\n",
      "During handling of the above exception, another exception occurred:\n",
      "\n",
      "Traceback (most recent call last):\n",
      "  File \"/usr/local/lib/python3.6/dist-packages/IPython/core/interactiveshell.py\", line 2044, in showtraceback\n",
      "    stb = value._render_traceback_()\n",
      "AttributeError: 'FileNotFoundError' object has no attribute '_render_traceback_'\n",
      "\n",
      "During handling of the above exception, another exception occurred:\n",
      "\n",
      "Traceback (most recent call last):\n",
      "  File \"/usr/local/lib/python3.6/dist-packages/IPython/core/interactiveshell.py\", line 3254, in run_ast_nodes\n",
      "    if (await self.run_code(code, result,  async_=asy)):\n",
      "  File \"/usr/local/lib/python3.6/dist-packages/IPython/core/interactiveshell.py\", line 3348, in run_code\n",
      "    self.showtraceback(running_compiled_code=True)\n",
      "  File \"/usr/local/lib/python3.6/dist-packages/IPython/core/interactiveshell.py\", line 2047, in showtraceback\n",
      "    value, tb, tb_offset=tb_offset)\n",
      "  File \"/usr/local/lib/python3.6/dist-packages/IPython/core/ultratb.py\", line 1415, in structured_traceback\n",
      "    self, etype, value, tb, tb_offset, number_of_lines_of_context)\n",
      "  File \"/usr/local/lib/python3.6/dist-packages/IPython/core/ultratb.py\", line 1315, in structured_traceback\n",
      "    self, etype, value, tb, tb_offset, number_of_lines_of_context\n",
      "  File \"/usr/local/lib/python3.6/dist-packages/IPython/core/ultratb.py\", line 1183, in structured_traceback\n",
      "    formatted_exceptions += self.prepare_chained_exception_message(evalue.__cause__)\n",
      "TypeError: must be str, not list\n",
      "\n",
      "During handling of the above exception, another exception occurred:\n",
      "\n",
      "Traceback (most recent call last):\n",
      "  File \"/usr/local/lib/python3.6/dist-packages/IPython/core/interactiveshell.py\", line 2044, in showtraceback\n",
      "    stb = value._render_traceback_()\n",
      "AttributeError: 'TypeError' object has no attribute '_render_traceback_'\n",
      "\n",
      "During handling of the above exception, another exception occurred:\n",
      "\n",
      "Traceback (most recent call last):\n",
      "  File \"/usr/local/lib/python3.6/dist-packages/IPython/core/ultratb.py\", line 1148, in get_records\n",
      "    return _fixed_getinnerframes(etb, number_of_lines_of_context, tb_offset)\n",
      "  File \"/usr/local/lib/python3.6/dist-packages/IPython/core/ultratb.py\", line 316, in wrapped\n",
      "    return f(*args, **kwargs)\n",
      "  File \"/usr/local/lib/python3.6/dist-packages/IPython/core/ultratb.py\", line 350, in _fixed_getinnerframes\n",
      "    records = fix_frame_records_filenames(inspect.getinnerframes(etb, context))\n",
      "  File \"/usr/lib/python3.6/inspect.py\", line 1490, in getinnerframes\n",
      "    frameinfo = (tb.tb_frame,) + getframeinfo(tb, context)\n",
      "  File \"/usr/lib/python3.6/inspect.py\", line 1448, in getframeinfo\n",
      "    filename = getsourcefile(frame) or getfile(frame)\n",
      "  File \"/usr/lib/python3.6/inspect.py\", line 696, in getsourcefile\n",
      "    if getattr(getmodule(object, filename), '__loader__', None) is not None:\n",
      "  File \"/usr/lib/python3.6/inspect.py\", line 725, in getmodule\n",
      "    file = getabsfile(object, _filename)\n",
      "  File \"/usr/lib/python3.6/inspect.py\", line 709, in getabsfile\n",
      "    return os.path.normcase(os.path.abspath(_filename))\n",
      "  File \"/usr/lib/python3.6/posixpath.py\", line 383, in abspath\n",
      "    cwd = os.getcwd()\n",
      "FileNotFoundError: [Errno 2] No such file or directory\n"
     ]
    },
    {
     "ename": "TypeError",
     "evalue": "must be str, not list",
     "output_type": "error",
     "traceback": [
      "\u001b[0;31m---------------------------------------------------------------------------\u001b[0m",
      "\u001b[0;31mKeyError\u001b[0m                                  Traceback (most recent call last)",
      "\u001b[0;32m/usr/lib/python3.6/pkgutil.py\u001b[0m in \u001b[0;36mget_importer\u001b[0;34m(path_item)\u001b[0m\n\u001b[1;32m    411\u001b[0m     \u001b[0;32mtry\u001b[0m\u001b[0;34m:\u001b[0m\u001b[0;34m\u001b[0m\u001b[0;34m\u001b[0m\u001b[0m\n\u001b[0;32m--> 412\u001b[0;31m         \u001b[0mimporter\u001b[0m \u001b[0;34m=\u001b[0m \u001b[0msys\u001b[0m\u001b[0;34m.\u001b[0m\u001b[0mpath_importer_cache\u001b[0m\u001b[0;34m[\u001b[0m\u001b[0mpath_item\u001b[0m\u001b[0;34m]\u001b[0m\u001b[0;34m\u001b[0m\u001b[0;34m\u001b[0m\u001b[0m\n\u001b[0m\u001b[1;32m    413\u001b[0m     \u001b[0;32mexcept\u001b[0m \u001b[0mKeyError\u001b[0m\u001b[0;34m:\u001b[0m\u001b[0;34m\u001b[0m\u001b[0;34m\u001b[0m\u001b[0m\n",
      "\u001b[0;31mKeyError\u001b[0m: ''",
      "\nDuring handling of the above exception, another exception occurred:\n",
      "\nDuring handling of the above exception, another exception occurred:\n",
      "\u001b[0;31mAttributeError\u001b[0m                            Traceback (most recent call last)",
      "\u001b[0;32m/usr/local/lib/python3.6/dist-packages/IPython/core/interactiveshell.py\u001b[0m in \u001b[0;36mshowtraceback\u001b[0;34m(self, exc_tuple, filename, tb_offset, exception_only, running_compiled_code)\u001b[0m\n\u001b[1;32m   2043\u001b[0m                         \u001b[0;31m# in the engines. This should return a list of strings.\u001b[0m\u001b[0;34m\u001b[0m\u001b[0;34m\u001b[0m\u001b[0;34m\u001b[0m\u001b[0m\n\u001b[0;32m-> 2044\u001b[0;31m                         \u001b[0mstb\u001b[0m \u001b[0;34m=\u001b[0m \u001b[0mvalue\u001b[0m\u001b[0;34m.\u001b[0m\u001b[0m_render_traceback_\u001b[0m\u001b[0;34m(\u001b[0m\u001b[0;34m)\u001b[0m\u001b[0;34m\u001b[0m\u001b[0;34m\u001b[0m\u001b[0m\n\u001b[0m\u001b[1;32m   2045\u001b[0m                     \u001b[0;32mexcept\u001b[0m \u001b[0mException\u001b[0m\u001b[0;34m:\u001b[0m\u001b[0;34m\u001b[0m\u001b[0;34m\u001b[0m\u001b[0m\n",
      "\u001b[0;31mAttributeError\u001b[0m: 'FileNotFoundError' object has no attribute '_render_traceback_'",
      "\nDuring handling of the above exception, another exception occurred:\n",
      "\u001b[0;31mTypeError\u001b[0m                                 Traceback (most recent call last)",
      "\u001b[0;32m/usr/local/lib/python3.6/dist-packages/IPython/core/interactiveshell.py\u001b[0m in \u001b[0;36mrun_code\u001b[0;34m(self, code_obj, result, async_)\u001b[0m\n\u001b[1;32m   3346\u001b[0m             \u001b[0;32mif\u001b[0m \u001b[0mresult\u001b[0m \u001b[0;32mis\u001b[0m \u001b[0;32mnot\u001b[0m \u001b[0;32mNone\u001b[0m\u001b[0;34m:\u001b[0m\u001b[0;34m\u001b[0m\u001b[0;34m\u001b[0m\u001b[0m\n\u001b[1;32m   3347\u001b[0m                 \u001b[0mresult\u001b[0m\u001b[0;34m.\u001b[0m\u001b[0merror_in_exec\u001b[0m \u001b[0;34m=\u001b[0m \u001b[0msys\u001b[0m\u001b[0;34m.\u001b[0m\u001b[0mexc_info\u001b[0m\u001b[0;34m(\u001b[0m\u001b[0;34m)\u001b[0m\u001b[0;34m[\u001b[0m\u001b[0;36m1\u001b[0m\u001b[0;34m]\u001b[0m\u001b[0;34m\u001b[0m\u001b[0;34m\u001b[0m\u001b[0m\n\u001b[0;32m-> 3348\u001b[0;31m             \u001b[0mself\u001b[0m\u001b[0;34m.\u001b[0m\u001b[0mshowtraceback\u001b[0m\u001b[0;34m(\u001b[0m\u001b[0mrunning_compiled_code\u001b[0m\u001b[0;34m=\u001b[0m\u001b[0;32mTrue\u001b[0m\u001b[0;34m)\u001b[0m\u001b[0;34m\u001b[0m\u001b[0;34m\u001b[0m\u001b[0m\n\u001b[0m\u001b[1;32m   3349\u001b[0m         \u001b[0;32melse\u001b[0m\u001b[0;34m:\u001b[0m\u001b[0;34m\u001b[0m\u001b[0;34m\u001b[0m\u001b[0m\n\u001b[1;32m   3350\u001b[0m             \u001b[0moutflag\u001b[0m \u001b[0;34m=\u001b[0m \u001b[0;32mFalse\u001b[0m\u001b[0;34m\u001b[0m\u001b[0;34m\u001b[0m\u001b[0m\n",
      "\u001b[0;32m/usr/local/lib/python3.6/dist-packages/IPython/core/interactiveshell.py\u001b[0m in \u001b[0;36mshowtraceback\u001b[0;34m(self, exc_tuple, filename, tb_offset, exception_only, running_compiled_code)\u001b[0m\n\u001b[1;32m   2045\u001b[0m                     \u001b[0;32mexcept\u001b[0m \u001b[0mException\u001b[0m\u001b[0;34m:\u001b[0m\u001b[0;34m\u001b[0m\u001b[0;34m\u001b[0m\u001b[0m\n\u001b[1;32m   2046\u001b[0m                         stb = self.InteractiveTB.structured_traceback(etype,\n\u001b[0;32m-> 2047\u001b[0;31m                                             value, tb, tb_offset=tb_offset)\n\u001b[0m\u001b[1;32m   2048\u001b[0m \u001b[0;34m\u001b[0m\u001b[0m\n\u001b[1;32m   2049\u001b[0m                     \u001b[0mself\u001b[0m\u001b[0;34m.\u001b[0m\u001b[0m_showtraceback\u001b[0m\u001b[0;34m(\u001b[0m\u001b[0metype\u001b[0m\u001b[0;34m,\u001b[0m \u001b[0mvalue\u001b[0m\u001b[0;34m,\u001b[0m \u001b[0mstb\u001b[0m\u001b[0;34m)\u001b[0m\u001b[0;34m\u001b[0m\u001b[0;34m\u001b[0m\u001b[0m\n",
      "\u001b[0;32m/usr/local/lib/python3.6/dist-packages/IPython/core/ultratb.py\u001b[0m in \u001b[0;36mstructured_traceback\u001b[0;34m(self, etype, value, tb, tb_offset, number_of_lines_of_context)\u001b[0m\n\u001b[1;32m   1413\u001b[0m             \u001b[0mself\u001b[0m\u001b[0;34m.\u001b[0m\u001b[0mtb\u001b[0m \u001b[0;34m=\u001b[0m \u001b[0mtb\u001b[0m\u001b[0;34m\u001b[0m\u001b[0;34m\u001b[0m\u001b[0m\n\u001b[1;32m   1414\u001b[0m         return FormattedTB.structured_traceback(\n\u001b[0;32m-> 1415\u001b[0;31m             self, etype, value, tb, tb_offset, number_of_lines_of_context)\n\u001b[0m\u001b[1;32m   1416\u001b[0m \u001b[0;34m\u001b[0m\u001b[0m\n\u001b[1;32m   1417\u001b[0m \u001b[0;34m\u001b[0m\u001b[0m\n",
      "\u001b[0;32m/usr/local/lib/python3.6/dist-packages/IPython/core/ultratb.py\u001b[0m in \u001b[0;36mstructured_traceback\u001b[0;34m(self, etype, value, tb, tb_offset, number_of_lines_of_context)\u001b[0m\n\u001b[1;32m   1313\u001b[0m             \u001b[0;31m# Verbose modes need a full traceback\u001b[0m\u001b[0;34m\u001b[0m\u001b[0;34m\u001b[0m\u001b[0;34m\u001b[0m\u001b[0m\n\u001b[1;32m   1314\u001b[0m             return VerboseTB.structured_traceback(\n\u001b[0;32m-> 1315\u001b[0;31m                 \u001b[0mself\u001b[0m\u001b[0;34m,\u001b[0m \u001b[0metype\u001b[0m\u001b[0;34m,\u001b[0m \u001b[0mvalue\u001b[0m\u001b[0;34m,\u001b[0m \u001b[0mtb\u001b[0m\u001b[0;34m,\u001b[0m \u001b[0mtb_offset\u001b[0m\u001b[0;34m,\u001b[0m \u001b[0mnumber_of_lines_of_context\u001b[0m\u001b[0;34m\u001b[0m\u001b[0;34m\u001b[0m\u001b[0m\n\u001b[0m\u001b[1;32m   1316\u001b[0m             )\n\u001b[1;32m   1317\u001b[0m         \u001b[0;32melif\u001b[0m \u001b[0mmode\u001b[0m \u001b[0;34m==\u001b[0m \u001b[0;34m'Minimal'\u001b[0m\u001b[0;34m:\u001b[0m\u001b[0;34m\u001b[0m\u001b[0;34m\u001b[0m\u001b[0m\n",
      "\u001b[0;32m/usr/local/lib/python3.6/dist-packages/IPython/core/ultratb.py\u001b[0m in \u001b[0;36mstructured_traceback\u001b[0;34m(self, etype, evalue, etb, tb_offset, number_of_lines_of_context)\u001b[0m\n\u001b[1;32m   1181\u001b[0m         \u001b[0mexception\u001b[0m \u001b[0;34m=\u001b[0m \u001b[0mself\u001b[0m\u001b[0;34m.\u001b[0m\u001b[0mget_parts_of_chained_exception\u001b[0m\u001b[0;34m(\u001b[0m\u001b[0mevalue\u001b[0m\u001b[0;34m)\u001b[0m\u001b[0;34m\u001b[0m\u001b[0;34m\u001b[0m\u001b[0m\n\u001b[1;32m   1182\u001b[0m         \u001b[0;32mif\u001b[0m \u001b[0mexception\u001b[0m\u001b[0;34m:\u001b[0m\u001b[0;34m\u001b[0m\u001b[0;34m\u001b[0m\u001b[0m\n\u001b[0;32m-> 1183\u001b[0;31m             \u001b[0mformatted_exceptions\u001b[0m \u001b[0;34m+=\u001b[0m \u001b[0mself\u001b[0m\u001b[0;34m.\u001b[0m\u001b[0mprepare_chained_exception_message\u001b[0m\u001b[0;34m(\u001b[0m\u001b[0mevalue\u001b[0m\u001b[0;34m.\u001b[0m\u001b[0m__cause__\u001b[0m\u001b[0;34m)\u001b[0m\u001b[0;34m\u001b[0m\u001b[0;34m\u001b[0m\u001b[0m\n\u001b[0m\u001b[1;32m   1184\u001b[0m             \u001b[0metype\u001b[0m\u001b[0;34m,\u001b[0m \u001b[0mevalue\u001b[0m\u001b[0;34m,\u001b[0m \u001b[0metb\u001b[0m \u001b[0;34m=\u001b[0m \u001b[0mexception\u001b[0m\u001b[0;34m\u001b[0m\u001b[0;34m\u001b[0m\u001b[0m\n\u001b[1;32m   1185\u001b[0m         \u001b[0;32melse\u001b[0m\u001b[0;34m:\u001b[0m\u001b[0;34m\u001b[0m\u001b[0;34m\u001b[0m\u001b[0m\n",
      "\u001b[0;31mTypeError\u001b[0m: must be str, not list"
     ]
    }
   ],
   "source": [
    "import autokeras as ak\n",
    "\n",
    "clf = ak.ImageClassifier()\n",
    "clf.fit(x_train, y_train)\n",
    "results = clf.predict(x_test)"
   ]
  },
  {
   "cell_type": "code",
   "execution_count": null,
   "metadata": {},
   "outputs": [],
   "source": []
  }
 ],
 "metadata": {
  "kernelspec": {
   "display_name": "Python 3",
   "language": "python",
   "name": "python3"
  },
  "language_info": {
   "codemirror_mode": {
    "name": "ipython",
    "version": 3
   },
   "file_extension": ".py",
   "mimetype": "text/x-python",
   "name": "python",
   "nbconvert_exporter": "python",
   "pygments_lexer": "ipython3",
   "version": "3.6.9"
  }
 },
 "nbformat": 4,
 "nbformat_minor": 2
}
